Workbook

Sheet Extrato
A1: Extrato de movimentações
J2: Saídas | K2: Entradas | L2: Capital de giro | M2: Lucro
J3: =SUMIF(Tabela4[Tipo],"Saída",Tabela4[Valor]) -> 542.74 | K3: =SUMIF(Tabela4[Tipo],"Entrada",Tabela4[Valor]) -> 536.39 | L3: =SUMIF(Tabela4[Categoria],"Capital de giro",Tabela4[Valor]) -> 4.94 | M3: =K3-J3+L3 -> -1.41
A4: Descrição | B4: Data | C4: Tipo | D4: Categoria | E4: Valor | F4: Origem | G4: Destino | H4: Recebedor
A5: Pagamento de salário semanal | B5: 45672 | C5: Saída | D5: Despesas | E5: 1.04 | F5: Banco inter | G5: Nubank | H5: Armando rodrigues progenio neto
A6: Pagamento de Dividendos MXRF11 | B6: 45683 | C6: Entrada | D6: Dividendos | E6: 0.1 | F6: MXRF11 | G6: Nubank | H6: Armando rodrigues progenio neto
A7: Empéstimo | B7: 45686 | C7: Saída | D7: Empréstimo | E7: 20 | F7: Banco inter | G7: Caixa econômica federal | H7: Armando rodrigues progenio neto
A8: Empéstimo | B8: 45687 | C8: Saída | D8: Empréstimo | E8: 5 | F8: Nubank | G8: Nubank | H8: Armando rodrigues progenio neto
A9: Rendimento Valor para despesas | B9: 45688 | C9: Entrada | D9: Lucro | E9: 0.01 | F9: Nubank | G9: Nubank | H9: Armando rodrigues progenio neto
A10: Pagamento de empréstimo | B10: 45696 | C10: Entrada | D10: Empréstimo | E10: 55.92 | F10: Nubank | G10: Nubank | H10: Armando rodrigues progenio neto
A11: Empéstimo | B11: 45689 | C11: Saída | D11: Empréstimo | E11: 28.5 | F11: Nubank | G11: Nubank | H11: Armando rodrigues progenio neto
A12: Empréstimo | B12: 45696 | C12: Saída | D12: Empréstimo | E12: =55.92-1.14 -> 54.78 | F12: Nubank | G12: Nubank | H12: Armando rodrigues progenio neto
A13: Pagamento de salário semanal de funcionários | B13: 45696 | C13: Saída | D13: Despesas | E13: 1.14 | F13: Nubank | G13: Nubank | H13: Armando rodrigues progenio neto
A14: Pagamento dividendos MXRF11 | B14: 45702 | C14: Entrada | D14: Dividendos | E14: 0.27 | F14: Nubank | G14: Nubank | H14: Armando rodrigues progenio neto
A15: Pagamento Consórcio | B15: 45706 | C15: Saída | D15: Consórcio | E15: 12 | F15: Nubank | G15: Nubank | H15: Armando rodrigues progenio neto
A16: Venda de 347 ações para Gênio consorcios | B16: 45706 | C16: Entrada | D16: Negociação | E16: 12.01 | F16: Nubank | G16: Nubank | H16: Armando rodrigues progenio neto
A17: Venda de ações 256 ações para genio consorcios | B17: 45708 | C17: Entrada | D17: Negociação | E17: 12.02 | F17: Nubank | G17: Nubank | H17: Armando rodrigues progenio neto
A18: Aplicação de dinheiro | B18: 45708 | C18: Saída | D18: Negociação | E18: 12.02 | F18: Nubank | G18: Nubank | H18: Armando rodrigues progenio neto
A19: Pagamento de empréstimo | B19: 45708 | C19: Entrada | D19: Negociação | E19: 56.19 | F19: Nubank | G19: Nubank | H19: Armando rodrigues progenio neto
A20: Aplicação de dinheiro | B20: 45708 | C20: Saída | D20: Capital de giro | E20: 1.12 | F20: Nubank | G20: Nubank | H20: Armando rodrigues progenio neto
A21: Rendimento Valor para despesas | B21: 45712 | C21: Entrada | D21: Lucro | E21: 0.01 | F21: Nubank | G21: Nubank | H21: Armando rodrigues progenio neto
A22: Aplicação de dinheiro | B22: 45712 | C22: Saída | D22: Capital de giro | E22: 0.01 | F22: Nubank | G22: Nubank | H22: Armando rodrigues progenio neto
A23: Rendimento valor caixa2 | B23: 45712 | C23: Entrada | D23: Lucro | E23: 0.01 | F23: Itaú | G23: Itaú | H23: Armando rodrigues progenio neto
A24: Rendimento empréstimos | B24: 45712 | C24: Entrada | D24: Lucro | E24: 0.02 | F24: Itaú | G24: Itaú | H24: Armando rodrigues progenio neto
... A38: Aplicação de valores | B38: 45723 | C38: Saída | D38: Capital de giro | E38: 0.01 | F38: Inter | G38: Inter | H38: Armando rodrigues progenio neto
A39: Empréstimo para pagar uber | B39: 45724 | C39: Saída | D39: Empréstimo | E39: =11-1.25 -> 9.75 | F39: Inter | G39: Nubank | H39: Armando rodrigues progenio neto
A40: Pagamento de funcionário | B40: 45724 | C40: Saída | D40: Despesas | E40: 1.25 | F40: Inter | G40: Nubank | H40: Armando rodrigues progenio neto
A41: Lucro Despesas | B41: 45727 | C41: Entrada | D41: Lucro | E41: 0.01 | F41: Nubank | G41: Nubank | H41: Armando rodrigues progenio neto
A42: Aplicação de valores | B42: 45727 | C42: Saída | D42: Capital de giro | E42: 0.01 | F42: Nubank | G42: Nubank | H42: Armando rodrigues progenio neto
A43: Lucro CDB | B43: 45727 | C43: Entrada | D43: Lucro | E43: 0.05 | F43: Nubank | G43: Nubank | H43: Armando rodrigues progenio neto
A44: Aplicação de valores | B44: 45727 | C44: Saída | D44: Capital de giro | E44: 0.05 | F44: Nubank | G44: Nubank | H44: Armando rodrigues progenio neto
A45: Lucro CDB | B45: 45730 | C45: Entrada | D45: Lucro | E45: 0.07 | F45: Inter | G45: Inter | H45: Armando rodrigues progenio neto
A46: Aplicação de valores | B46: 45730 | C46: Saída | D46: Capital de giro | E46: 0.07 | F46: Inter | G46: Inter | H46: Armando rodrigues progenio neto
A47: Venda de 156 ações para o consórcio | B47: 45730 | C47: Entrada | D47: Negociação | E47: 18.02 | F47: Nubank | G47: Inter | H47: Armando rodrigues progenio neto
A48: Aplicação de valores | B48: 45730 | C48: Saída | D48: Negociação | E48: 18.02 | F48: Inter | G48: Inter | H48: Armando rodrigues progenio neto
A49: Pagamento de empréstimo | B49: 45730 | C49: Entrada | D49: Empréstimo | E49: 10 | F49: Nubank | G49: Nubank | H49: Armando rodrigues progenio neto
A50: Lucro despesas | B50: 45730 | C50: Entrada | D50: Lucro | E50: 0.01 | F50: Nubank | G50: Nubank | H50: Armando rodrigues progenio neto
A51: Aplicação de valores | B51: 45730 | C51: Saída | D51: Capital de giro | E51: 0.01 | F51: Nubank | G51: Nubank | H51: Armando rodrigues progenio neto
... A59: Pagamento de empréstimo | B59: 45736 | C59: Entrada | D59: Empréstimo | E59: 95.33 | F59: Nubank | G59: Inter | H59: Armando rodrigues progenio neto
A60: Taxa equilíbrio mensal | B60: 45736 | C60: Saída | D60: Taxa | E60: =1.5+1.89 -> 3.39 | F60: Inter | G60: - | H60: Armando rodrigues progenio neto
...

Sheet Financeiro
A1: Gestão de capital | J1: Divisão de capital
A4: Capital investido | B4: Capital total | C4: Lucro | D4: Pagamento De funcionários | E4: Ultimo salário pago | F4: Saldo em caixa | G4: Saldo Projetado | I4: Tipo | J4: CDB | K4: Ação/BDR | L4: Dolar | M4: FII | N4: Caixa 2 | O4: Empréstimo | P4: Despesas | Q4: Day trader | R4: ETF | S4: Tesouro direto | T4: Preço de mercado
A5: =SUM('Investimento CDB'!J6+'Investimento em renda variável'!R5)+SUM(Tabela10[Valor de depósito])+SUM(Outros!H5,Outros!R5,Outros!Z5)+'Tesouro direto'!J4 -> 478.23609 | B5: =Tabela3[[#This Row],[Capital investido]]+Tabela3[[#This Row],[Lucro]] -> 480.86117 | C5: =SUM('Investimento CDB'!J12+'Investimento em renda variável'!R9+Dolar!K8+Extrato!M3) -> 2.6250834 | D5: =1.04+1.14+1.25 -> 3.43 | E5: 1.25 | F5: =B5 -> 480.86117 | G5: {=[1]!Tabela3[Saldo a receber]} -> #REF! | I5: % | J5: =('Investimento CDB'!J6/Tabela3[[#This Row],[Capital total]])*100/100 -> 0.22531678 | K5: ='Investimento em renda variável'!R21/Tabela3[[#This Row],[Capital total]]*1 -> 0.18847436 | L5: =(Dolar!M5/Tabela3[[#This Row],[Capital total]])*100/100 -> 0.25925379 | M5: =('Investimento em renda variável'!R13/Tabela3[[#This Row],[Capital total]])*1 -> 0.1699451 | N5: =Outros!R5/Tabela3[[#This Row],[Capital total]]*1 -> 0.01229045 | O5: =Outros!H5/Tabela3[[#This Row],[Capital total]]*100/100 -> 0.007195424 | P5: =Outros!Z5/Tabela3[[#This Row],[Capital total]]*1 -> 0.013455027 | Q5: =('Investimento em renda variável'!R18/Tabela3[[#This Row],[Capital total]])*1 -> 0 | R5: =('Investimento em renda variável'!R29/Tabela3[[#This Row],[Capital total]])*1 -> 0.044295529 | S5: ='Tesouro direto'!J4/(Tabela3[[#This Row],[Capital total]]*1) -> 0.07927444 | T5: 5e-05
I6: $ | J6: {=Tabela3[Capital total]+(Tabela3[Capital total]*J5)-Tabela3[Capital total]} -> 108.34609 | K6: {=Tabela3[Capital total]+(Tabela3[Capital total]*K5)-Tabela3[Capital total]} -> 90.63 | L6: {=Tabela3[Capital total]+(Tabela3[Capital total]*L5)-Tabela3[Capital total]} -> 124.66508 | M6: {=Tabela3[Capital total]+(Tabela3[Capital total]*M5)-Tabela3[Capital total]} -> 81.72 | N6: {=Tabela3[Capital total]+(Tabela3[Capital total]*N5)-Tabela3[Capital total]} -> 5.91 | O6: {=Tabela3[Capital total]+(Tabela3[Capital total]*O5)-Tabela3[Capital total]} -> 3.46 | P6: {=Tabela3[Capital total]+(Tabela3[Capital total]*P5)-Tabela3[Capital total]} -> 6.47 | Q6: {=Tabela3[Capital total]+(Tabela3[Capital total]*Q5)-Tabela3[Capital total]} -> 0 | R6: ='Investimento em renda variável'!R29 -> 21.3 | S6: ='Tesouro direto'!J4 -> 38.12 | T6: {=Tabela3[Capital total]/4000} -> 0.12021529
K10: =SUM(J5:Q5) -> 0.87593093 | P10: =SUM(J6:S6) -> 480.62117

Sheet Investimento CDB
A5: Instituição | B5: Observação | C5: Valor | D5: I.P.C.A | E5: Valor projetado | F5: Data | G5: Conta Inicial | H5: Futuro | J5: Total Aplicado | L5: Sempre colocar o valor mais o I.P.C.A do mês.
A6: Banco Inter | B6: Meta de guardar no porquinho 1 real por dia | C6: 1 | D6: 0.0046 | E6: =C6+(D6*C6) -> 1.0046 | F6: 45663 | G6: Nubank | H6: =IF(Tabela2[[#This Row],[Data]]-TODAY()<1,"Não","Sim") -> Não | J6: =SUMIFS(Tabela2[Valor],Tabela2[Futuro],"Não")+J12 -> 108.34609 | L6: Ainda vou decidir o que vou fazer com esse dinheiro.
A7: Banco Inter | B7: Meta de guardar no porquinho 1 real por dia | C7: =E6 -> 1.0046 | D7: 0.0039 | E7: =C7+(D7*C7) -> 1.0085179 | F7: 45664 | G7: Nubank | H7: =IF(Tabela2[[#This Row],[Data]]-TODAY()<1,"Não","Sim") -> Não
A8: Banco Inter | B8: Meta de guardar no porquinho 1 real por dia | C8: =E7 -> 1.0085179 | D8: 0.0039 | E8: =C8+(D8*C8) -> 1.0124512 | F8: 45665 | G8: Nubank | H8: =IF(Tabela2[[#This Row],[Data]]-TODAY()<1,"Não","Sim") -> Não | J8: Dias | L8: Buscar o valor investido de outras corretoras
A9: Banco Inter | B9: Meta de guardar no porquinho 1 real por dia | C9: 1.03 | D9: 0.0039 | E9: =C9+(D9*C9) -> 1.034017 | F9: 45666 | G9: Nubank | H9: =IF(Tabela2[[#This Row],[Data]]-TODAY()<1,"Não","Sim") -> Não | J9: =COUNTA(Tabela2[Instituição]) -> 89
A10: Banco Inter | B10: Meta de guardar no porquinho 1 real por dia | C10: 1.06 | D10: 0.0039 | E10: =C10+(D10*C10) -> 1.064134 | F10: 45667 | G10: Nubank | H10: =IF(Tabela2[[#This Row],[Data]]-TODAY()<1,"Não","Sim") -> Não
A11: Banco Inter | B11: Meta de guardar no porquinho 1 real por dia | C11: =E10 -> 1.064134 | D11: 0.0039 | E11: =C11+(D11*C11) -> 1.0682841 | F11: 45668 | G11: Nubank | H11: =IF(Tabela2[[#This Row],[Data]]-TODAY()<1,"Não","Sim") -> Não | J11: Rendimento
A12: Banco Inter | B12: Meta de guardar no porquinho 1 real por dia | C12: =E11 -> 1.0682841 | D12: 0.0039 | E12: =C12+(D12*C12) -> 1.0724504 | F12: 45669 | G12: Nubank | H12: =IF(Tabela2[[#This Row],[Data]]-TODAY()<1,"Não","Sim") -> Não | J12: 0.51
A13: Banco Inter | B13: Meta de guardar no porquinho 1 real por dia | C13: =E12 -> 1.0724504 | D13: 0.0039 | E13: =C13+(D13*C13) -> 1.076633 | F13: 45670 | G13: Nubank | H13: =IF(Tabela2[[#This Row],[Data]]-TODAY()<1,"Não","Sim") -> Não
A14: Banco inter | B14: Meta de guardar no porquinho 1 real por dia | C14: =E13 -> 1.076633 | D14: 0.0039 | E14: =C14+(D14*C14) -> 1.0808319 | F14: 45671 | G14: Nubank | H14: =IF(Tabela2[[#This Row],[Data]]-TODAY()<1,"Não","Sim") -> Não
A15: Banco inter | B15: Meta de guardar no porquinho 1 real por dia | C15: =E14 -> 1.0808319 | D15: 0.0039 | E15: =C15+(D15*C15) -> 1.0850471 | F15: 45672 | G15: Nubank | H15: =IF(Tabela2[[#This Row],[Data]]-TODAY()<1,"Não","Sim") -> Não
A16: Banco Inter | B16: Meta de guardar no porquinho 1 real por dia | C16: =E15 -> 1.0850471 | D16: 0.0046 | E16: =C16+(D16*C16) -> 1.0900383 | F16: 45673 | G16: Nubank | H16: =IF(Tabela2[[#This Row],[Data]]-TODAY()<1,"Não","Sim") -> Não
A17: Banco inter | B17: Meta de guardar no porquinho 1 real por dia | C17: =E16 -> 1.0900383 | D17: 0.0046 | E17: =C17+(D17*C17) -> 1.0950525 | F17: 45674 | G17: Nubank | H17: =IF(Tabela2[[#This Row],[Data]]-TODAY()<1,"Não","Sim") -> Não
A18: Banco inter | B18: Meta de guardar no porquinho 1 real por dia | C18: =E17 -> 1.0950525 | D18: 0.0046 | E18: =C18+(D18*C18) -> 1.1000897 | F18: 45675 | G18: Nubank | H18: =IF(Tabela2[[#This Row],[Data]]-TODAY()<1,"Não","Sim") -> Não
A19: Banco Inter | B19: Meta de guardar no porquinho 1 real por dia | C19: =E18 -> 1.1000897 | D19: 0.0046 | E19: =C19+(D19*C19) -> 1.1051501 | F19: 45676 | G19: Banco inter | H19: =IF(Tabela2[[#This Row],[Data]]-TODAY()<1,"Não","Sim") -> Não
A20: Banco Inter | B20: Meta de guardar no porquinho 1 real por dia | C20: =E19 -> 1.1051501 | D20: 0.0046 | E20: =C20+(D20*C20) -> 1.1102338 | F20: 45677 | G20: Banco inter | H20: =IF(Tabela2[[#This Row],[Data]]-TODAY()<1,"Não","Sim") -> Não
A21: Banco Inter | B21: Meta de guardar no porquinho 1 real por dia | C21: =E20 -> 1.1102338 | D21: 0.0046 | E21: =C21+(D21*C21) -> 1.1153409 | F21: 45678 | G21: Banco inter | H21: =IF(Tabela2[[#This Row],[Data]]-TODAY()<1,"Não","Sim") -> Não
A22: Banco Inter | B22: Meta de guardar no porquinho 1 real por dia | C22: =E21 -> 1.1153409 | D22: 0.0046 | E22: =C22+(D22*C22) -> 1.1204715 | F22: 45679 | G22: Banco inter | H22: =IF(Tabela2[[#This Row],[Data]]-TODAY()<1,"Não","Sim") -> Não
A23: Banco inter | B23: Meta de guardar no porquinho 1 real por dia | C23: =E22 -> 1.1204715 | D23: 0.0046 | E23: =C23+(D23*C23) -> 1.1256257 | F23: 45680 | G23: Banco inter | H23: =IF(Tabela2[[#This Row],[Data]]-TODAY()<1,"Não","Sim") -> Não
A24: Banco Inter | B24: Meta de guardar no porquinho 1 real por dia | C24: =E23 -> 1.1256257 | D24: 0.0046 | E24: =C24+(D24*C24) -> 1.1308035 | F24: 45681 | G24: Banco inter | H24: =IF(Tabela2[[#This Row],[Data]]-TODAY()<1,"Não","Sim") -> Não
... A45: Banco Inter | B45: Meta de guardar no porquinho 1 real por dia | C45: =E44 -> 1.1903843 | D45: 0.0106 | E45: =C45+(D45*C45) -> 1.2030024 | F45: 45702 | G45: Nubank | H45: =IF(Tabela2[[#This Row],[Data]]-TODAY()<1,"Não","Sim") -> Não
A46: Banco Inter | B46: Meta de guardar no porquinho 1 real por dia | C46: =E45 -> 1.2030024 | D46: 0.0106 | E46: =C46+(D46*C46) -> 1.2157542 | F46: 45703 | G46: Nubank | H46: =IF(Tabela2[[#This Row],[Data]]-TODAY()<1,"Não","Sim") -> Não | K46: =SUM(C43:C62) -> 25.789553
A47: Banco Inter | B47: Meta de guardar no porquinho 1 real por dia | C47: =E46 -> 1.2157542 | D47: 0.0106 | E47: =C47+(D47*C47) -> 1.2286412 | F47: 45704 | G47: Nubank | H47: =IF(Tabela2[[#This Row],[Data]]-TODAY()<1,"Não","Sim") -> Não
A48: Banco Inter | B48: Meta de guardar no porquinho 1 real por dia | C48: =E47 -> 1.2286412 | D48: 0.0106 | E48: =C48+(D48*C48) -> 1.2416648 | F48: 45705 | G48: Nubank | H48: =IF(Tabela2[[#This Row],[Data]]-TODAY()<1,"Não","Sim") -> Não
A49: Banco Inter | B49: Meta de guardar no porquinho 1 real por dia | C49: 1.24 | D49: 0.0106 | E49: =C49+(D49*C49) -> 1.253144 | F49: 45706 | G49: Nubank | H49: =IF(Tabela2[[#This Row],[Data]]-TODAY()<1,"Não","Sim") -> Não
A50: Banco Inter | B50: Meta de guardar no porquinho 1 real por dia | C50: =E49 -> 1.253144 | D50: 0.0106 | E50: =C50+(D50*C50) -> 1.2664273 | F50: 45707 | G50: Nubank | H50: =IF(Tabela2[[#This Row],[Data]]-TODAY()<1,"Não","Sim") -> Não
A51: Banco Inter | B51: Meta de guardar no porquinho 1 real por dia | C51: =E50 -> 1.2664273 | D51: 0.0106 | E51: =C51+(D51*C51) -> 1.2798515 | F51: 45708 | G51: Nubank | H51: =IF(Tabela2[[#This Row],[Data]]-TODAY()<1,"Não","Sim") -> Não
A52: Banco Inter | B52: Meta de guardar no porquinho 1 real por dia | C52: =E51 -> 1.2798515 | D52: 0.0106 | E52: =C52+(D52*C52) -> 1.2934179 | F52: 45709 | G52: Nubank | H52: =IF(Tabela2[[#This Row],[Data]]-TODAY()<1,"Não","Sim") -> Não
A53: Banco Inter | B53: Meta de guardar no porquinho 1 real por dia | C53: =E52 -> 1.2934179 | D53: 0.0106 | E53: =C53+(D53*C53) -> 1.3071281 | F53: 45710 | G53: Nubank | H53: =IF(Tabela2[[#This Row],[Data]]-TODAY()<1,"Não","Sim") -> Não
A54: Banco Inter | B54: Meta de guardar no porquinho 1 real por dia | C54: =E53 -> 1.3071281 | D54: 0.0106 | E54: =C54+(D54*C54) -> 1.3209837 | F54: 45711 | G54: Nubank | H54: =IF(Tabela2[[#This Row],[Data]]-TODAY()<1,"Não","Sim") -> Não
A55: Banco Inter | B55: Meta de guardar no porquinho 1 real por dia | C55: =E54 -> 1.3209837 | D55: 0.0106 | E55: =C55+(D55*C55) -> 1.3349861 | F55: 45712 | G55: Nubank | H55: =IF(Tabela2[[#This Row],[Data]]-TODAY()<1,"Não","Sim") -> Não
A56: Banco Inter | B56: Meta de guardar no porquinho 1 real por dia | C56: =E55 -> 1.3349861 | D56: 0.0106 | E56: =C56+(D56*C56) -> 1.3491369 | F56: 45713 | G56: Nubank | H56: =IF(Tabela2[[#This Row],[Data]]-TODAY()<1,"Não","Sim") -> Não
A57: Banco Inter | B57: Meta de guardar no porquinho 1 real por dia | C57: =E56 -> 1.3491369 | D57: 0.0106 | E57: =C57+(D57*C57) -> 1.3634378 | F57: 45714 | G57: Nubank | H57: =IF(Tabela2[[#This Row],[Data]]-TODAY()<1,"Não","Sim") -> Não
A58: Banco Inter | B58: Meta de guardar no porquinho 1 real por dia | C58: =E57 -> 1.3634378 | D58: 0.0106 | E58: =C58+(D58*C58) -> 1.3778902 | F58: 45715 | G58: Nubank | H58: =IF(Tabela2[[#This Row],[Data]]-TODAY()<1,"Não","Sim") -> Não
A59: Banco Inter | B59: Meta de guardar no porquinho 1 real por dia | C59: =E58 -> 1.3778902 | D59: 0.0106 | E59: =C59+(D59*C59) -> 1.3924959 | F59: 45716 | G59: Nubank | H59: =IF(Tabela2[[#This Row],[Data]]-TODAY()<1,"Não","Sim") -> Não
A60: Banco Inter | B60: Meta de guardar no porquinho 1 real por dia | C60: =E59 -> 1.3924959 | D60: 0.0106 | E60: =C60+(D60*C60) -> 1.4072563 | F60: 45717 | G60: Nubank | H60: =IF(Tabela2[[#This Row],[Data]]-TODAY()<1,"Não","Sim") -> Não
A61: Banco Inter | B61: Meta de guardar no porquinho 1 real por dia | C61: =E60 -> 1.4072563 | D61: 0.0106 | E61: =C61+(D61*C61) -> 1.4221733 | F61: 45718 | G61: Nubank | H61: =IF(Tabela2[[#This Row],[Data]]-TODAY()<1,"Não","Sim") -> Não
... A79: Banco Inter | B79: Meta de guardar no porquinho 1 real por dia | C79: =E78 -> 1.7013768 | D79: 0.0106 | E79: =C79+(D79*C79) -> 1.7194114 | F79: 45736 | G79: Nubank | H79: =IF(Tabela2[[#This Row],[Data]]-TODAY()<1,"Não","Sim") -> Não
A80: Banco Inter | B80: Meta de guardar no porquinho 1 real por dia | C80: =E79 -> 1.7194114 | D80: 0.0106 | E80: =C80+(D80*C80) -> 1.7376371 | F80: 45737 | G80: Nubank | H80: =IF(Tabela2[[#This Row],[Data]]-TODAY()<1,"Não","Sim") -> Não | J80: =SUM(C80:C84) -> 8.7812567
A81: Banco Inter | B81: Meta de guardar no porquinho 1 real por dia | C81: =E80 -> 1.7376371 | D81: 0.0106 | E81: =C81+(D81*C81) -> 1.7560561 | F81: 45738 | G81: Nubank | H81: =IF(Tabela2[[#This Row],[Data]]-TODAY()<1,"Não","Sim") -> Não
...

Sheet Outros
A1: Caixa empréstimos | L1: Caixa 2 | S1: Despesas
A4: Banco | B4: Nome | C4: Tipo de Transação | D4: Valor | E4: Data | H4: Valor total | I4: Selic | J4: I.P.C.A | L4: Banco | M4: Nome | N4: Valor | O4: Data | P4: Tipo de transação | R4: Valor total | T4: Banco | U4: Nome | V4: Valor | W4: Data | X4: Tipo de Transação | Z4: Valor total
A5: Iti | B5: Empréstimos | C5: Entrada | D5: 2.16 | E5: 45677 | H5: =SUMIF(Tabela7[Tipo de Transação],"Entrada",Tabela7[Valor])-SUMIF(Tabela7[Tipo de Transação],"Saída",Tabela7[Valor]) -> 3.46 | I5: 0.1325 | J5: 0.0011 | L5: Iti | M5: Caixa 2 | N5: 3 | O5: 45677 | P5: Entrada | R5: =SUMIFS(Tabela79[Valor],Tabela79[Tipo de transação],"Entrada")-SUMIF(Tabela79[Tipo de transação],"Saída",Tabela79[Valor]) -> 5.91 | T5: Nubank | U5: Despesas | V5: 5 | W5: 45682 | X5: Entrada | Z5: =SUMIF(Tabela7911[Tipo de Transação],"Entrada",Tabela7911[Valor])-SUMIF(Tabela7911[Tipo de Transação],"Saída",Tabela7911[Valor])+0.01 -> 6.47
A6: iti | B6: Empréstimos | C6: Saída | D6: 20 | E6: 45686 | L6: Iti | M6: Caixa 2 | N6: 1.81 | O6: 45678 | P6: Saída | T6: Nubank | U6: Despesas | V6: 1.4 | W6: 45687 | X6: Entrada
A7: Iti | B7: Empréstimos | C7: Entrada | D7: 20 | E7: 45686 | L7: Itaú | M7: Caixa 2 | N7: 0.77 | O7: 45708 | P7: Entrada | T7: Nubank | U7: Despesas | V7: 0.01 | W7: 45712 | X7: Entrada
A8: Nubank | B8: Empréstimos | C8: Entrada | D8: 5 | E8: 45686 | L8: Itaú | M8: Caixa 2 | N8: 0.01 | O8: 45708 | P8: Entrada | T8: Nubank | U8: Despesas | V8: 0.01 | W8: 45717 | X8: Entrada
A9: Nubank | B9: Empréstimos | C9: Saída | D9: 5 | E9: 45687 | L9: Itaú | M9: Caixa 2 | N9: 0.94 | O9: 45730 | P9: Entrada | T9: Nubank | U9: Despesas | V9: 0.01 | W9: 45727 | X9: Entrada
A10: Itaú | B10: Empréstimos | C10: Entrada | D10: 0.02 | E10: 45712 | L10: Itaú | M10: Caixa 2 | N10: 3 | O10: 45737 | P10: Entrada | T10: Nubank | U10: Despesas | V10: 0.01 | W10: 45730 | X10: Entrada
A11: Itaú | B11: Empréstimos | C11: Entrada | D11: 1.28 | E11: 45734 | T11: Nubank | U11: Despesas | V11: 0.02 | W11: 45741 | X11: Entrada

Sheet Dolar
A1: Capital em dólar
Q2: Sempre colocar o valor mais o I.P.C.A do mês.
L3: #VALUE! | Q3: Ainda vou decidir o que vou fazer com esse dinheiro.
A4: Remetente | B4: Destino | C4: Valor de depósito | D4: Cotação | E4: Taxas | F4: Valor em dólar | G4: Data | I4: Total | K4: Cotação atual | M4: Total em reais
A5: Nubank | B5: Banco inter Global Account | C5: 10 | D5: 6.1 | E5: 0.11 | F5: =(C5-E5)/D5 -> 1.6213115 | G5: 45664 | I5: =SUM(Tabela10[Valor em dólar]) -> 21.718656 | K5: {=_FV(L3,"Preço")} -> 5.74 | M5: =K5*I5 -> 124.66508 | Q5: Buscar o valor investido de outras corretoras
A6: Nubank | B6: Banco inter Global Account | C6: 10 | D6: 6.05 | E6: 0.11 | F6: =(C6-E6)/D6 -> 1.6347107 | G6: 45671
A7: Nubank | B7: Banco inter Global Account | C7: 10 | D7: 5.9 | E7: 0.11 | F7: =(C7-E7)/D7 -> 1.6762712 | G7: 45684 | I7: Aplicado | K7: Lucro
A8: Nubank | B8: Banco inter Global Account | C8: 10 | D8: 5.7 | E8: 0.11 | F8: =(C8-E8)/D8 -> 1.7350877 | G8: 45708 | I8: =SUM(Tabela10[Valor de depósito]) -> 127.68 | K8: =M5-I8 -> -3.0149166
A9: Nubank | B9: Banco inter Global Account | C9: 19.68 | D9: 5.78 | E9: 0.43 | F9: =(C9-E9)/D9 -> 3.3304498 | G9: 45695
A10: Inter | B10: Banco inter Global Account | C10: 8.97 | D10: 5.74 | E10: 0.2 | F10: =(C10-E10)/D10 -> 1.5278746 | G10: 45730
A11: Inter | B11: Banco inter Global Account | C11: 49.03 | D11: 5.68 | E11: 0.9 | F11: =(C11-E11)/D11 -> 8.4735915 | G11: 45736
A12: Inter | B12: Banco inter Global Account | C12: 10 | D12: 5.6998 | E12: 0.2 | F12: =(C12-E12)/D12 -> 1.7193586 | G12: 45741

Sheet Investimento em renda variável
A4: Instituição | B4: Observação | C4: Ticker | D4: Nome do ativo | E4: QTD | F4: Valor da compra | G4: Preço Atual/Venda | H4: Data | I4: Dividendos pagos | J4: Lucro | K4: Lucro Real | L4: Média de lucro diário | M4: Em posse | N4: Total | O4: Tipo | P4: Operação | R4: Total aplicado
A5: Nubank | C5: {=_FV(Tabela27[[#This Row],[Nome do ativo]],"Símbolo do ticker",TRUE)} -> MXRF11 | D5: #VALUE! | E5: 1 | F5: 9.29 | G5: {=_FV(Tabela27[[#This Row],[Nome do ativo]],"Preço")*Tabela27[[#This Row],[QTD]]} -> 9.08 | H5: 45632 | I5: =0.19+0.09 -> 0.28 | J5: =(Tabela27[[#This Row],[Preço Atual/Venda]]-Tabela27[[#This Row],[Valor da compra]]) -> -0.21 | K5: =Tabela27[[#This Row],[Lucro]]+Tabela27[[#This Row],[Dividendos pagos]] -> 0.07 | L5: =J5/(IF(TODAY()-H5=0,1,TODAY()-H5)) -> -0.001875 | M5: Sim | N5: =Tabela27[[#This Row],[Valor da compra]]+Tabela27[[#This Row],[Lucro]] -> 9.08 | O5: FII | P5: Renda variável | R5: =SUMIF(Tabela27[Em posse],"Sim",Tabela27[Valor da compra]) -> 188.25
A6: Nubank | C6: {=_FV(Tabela27[[#This Row],[Nome do ativo]],"Símbolo do ticker",TRUE)} -> MXRF11 | D6: =D5 -> #VALUE! | E6: 1 | F6: 9.49 | G6: {=_FV(Tabela27[[#This Row],[Nome do ativo]],"Preço")*Tabela27[[#This Row],[QTD]]} -> 9.08 | H6: 45663 | I6: 0.18 | J6: =(Tabela27[[#This Row],[Preço Atual/Venda]]-Tabela27[[#This Row],[Valor da compra]]) -> -0.41 | K6: =Tabela27[[#This Row],[Lucro]]+Tabela27[[#This Row],[Dividendos pagos]] -> -0.23 | L6: =J6/(IF(TODAY()-H6=0,1,TODAY()-H6)) -> -0.0050617284 | M6: Sim | N6: =Tabela27[[#This Row],[Valor da compra]]+Tabela27[[#This Row],[Lucro]] -> 9.08 | O6: FII | P6: Renda variável | T6: Sempre colocar o valor mais o I.P.C.A do mês.
A7: Rico | C7: {=_FV(Tabela27[[#This Row],[Nome do ativo]],"Símbolo do ticker",TRUE)} -> MXRF11 | D7: #VALUE! | E7: 1 | F7: 9.21 | G7: {=_FV(Tabela27[[#This Row],[Nome do ativo]],"Preço")*Tabela27[[#This Row],[QTD]]} -> 9.08 | H7: 45670 | I7: 0 | J7: =(Tabela27[[#This Row],[Preço Atual/Venda]]-Tabela27[[#This Row],[Valor da compra]]) -> -0.13 | K7: =Tabela27[[#This Row],[Lucro]]+Tabela27[[#This Row],[Dividendos pagos]] -> -0.13 | L7: =J7/(IF(TODAY()-H7=0,1,TODAY()-H7)) -> -0.0017567568 | M7: Não | N7: =Tabela27[[#This Row],[Valor da compra]]+Tabela27[[#This Row],[Lucro]] -> 9.08 | O7: FII | P7: Day Trader | R7: Lucro total | T7: Ainda vou decidir o que vou fazer com esse dinheiro.
A8: Nubank | C8: MXRF11 | D8: #VALUE! | E8: 1 | F8: 9.17 | G8: {=_FV(Tabela27[[#This Row],[Nome do ativo]],"Preço")*Tabela27[[#This Row],[QTD]]} -> 9.08 | H8: 45677 | I8: 0.18 | J8: =(Tabela27[[#This Row],[Preço Atual/Venda]]-Tabela27[[#This Row],[Valor da compra]]) -> -0.09 | K8: =Tabela27[[#This Row],[Lucro]]+Tabela27[[#This Row],[Dividendos pagos]] -> 0.09 | L8: =J8/(IF(TODAY()-H8=0,1,TODAY()-H8)) -> -0.0013432836 | M8: Sim | N8: =Tabela27[[#This Row],[Valor da compra]]+Tabela27[[#This Row],[Lucro]] -> 9.08 | O8: FII | P8: Renda variável
A9: Rico | C9: {=_FV(Tabela27[[#This Row],[Nome do ativo]],"Símbolo do ticker",TRUE)} -> MXRF11 | D9: #VALUE! | E9: 1 | F9: 9.18 | G9: {=_FV(Tabela27[[#This Row],[Nome do ativo]],"Preço")*Tabela27[[#This Row],[QTD]]} -> 9.08 | H9: 45677 | J9: =(Tabela27[[#This Row],[Preço Atual/Venda]]-Tabela27[[#This Row],[Valor da compra]]) -> -0.1 | K9: =Tabela27[[#This Row],[Lucro]]+Tabela27[[#This Row],[Dividendos pagos]] -> -0.1 | L9: =J9/(IF(TODAY()-H9=0,1,TODAY()-H9)) -> -0.0014925373 | M9: Não | N9: =Tabela27[[#This Row],[Valor da compra]]+Tabela27[[#This Row],[Lucro]] -> 9.08 | O9: FII | P9: Day Trader | R9: =SUM(Tabela27[Lucro]) -> 6.54 | T9: Buscar o valor investido de outras corretoras
A10: Nubank | B10: Tem que vender pois o risco é muito alto | C10: {=_FV(Tabela27[[#This Row],[Nome do ativo]],"Símbolo do ticker",TRUE)} -> UCAS3 | D10: #VALUE! | E10: 1 | F10: 1.81 | G10: {=_FV(Tabela27[[#This Row],[Nome do ativo]],"Preço")*Tabela27[[#This Row],[QTD]]} -> 1.51 | H10: 45680 | J10: =(Tabela27[[#This Row],[Preço Atual/Venda]]-Tabela27[[#This Row],[Valor da compra]]) -> -0.3 | K10: =Tabela27[[#This Row],[Lucro]]+Tabela27[[#This Row],[Dividendos pagos]] -> -0.3 | L10: =J10/(IF(TODAY()-H10=0,1,TODAY()-H10)) -> -0.0046875 | M10: Sim | N10: =Tabela27[[#This Row],[Valor da compra]]+Tabela27[[#This Row],[Lucro]] -> 1.51 | O10: BDR | P10: Renda variável
A11: Rico | C11: {=_FV(Tabela27[[#This Row],[Nome do ativo]],"Símbolo do ticker",TRUE)} -> B3SA3 | D11: #VALUE! | E11: 1 | F11: 11.12 | G11: {=_FV(Tabela27[[#This Row],[Nome do ativo]],"Preço")*Tabela27[[#This Row],[QTD]]} -> 12.39 | H11: 45688 | J11: =(Tabela27[[#This Row],[Preço Atual/Venda]]-Tabela27[[#This Row],[Valor da compra]]) -> 1.27 | K11: =Tabela27[[#This Row],[Lucro]]+Tabela27[[#This Row],[Dividendos pagos]] -> 1.27 | L11: =J11/(IF(TODAY()-H11=0,1,TODAY()-H11)) -> 0.022678571 | M11: Não | N11: =Tabela27[[#This Row],[Valor da compra]]+Tabela27[[#This Row],[Lucro]] -> 12.39 | O11: BDR | P11: Day Trader | R11: Total FII
A12: Rico | C12: {=_FV(Tabela27[[#This Row],[Nome do ativo]],"Símbolo do ticker",TRUE)} -> MXRF11 | D12: #VALUE! | E12: 1 | F12: 8.98 | G12: {=_FV(Tabela27[[#This Row],[Nome do ativo]],"Preço")*Tabela27[[#This Row],[QTD]]} -> 9.08 | H12: 45692 | J12: =(Tabela27[[#This Row],[Preço Atual/Venda]]-Tabela27[[#This Row],[Valor da compra]]) -> 0.1 | K12: =Tabela27[[#This Row],[Lucro]]+Tabela27[[#This Row],[Dividendos pagos]] -> 0.1 | L12: =J12/(IF(TODAY()-H12=0,1,TODAY()-H12)) -> 0.0019230769 | M12: Não | N12: =Tabela27[[#This Row],[Valor da compra]]+Tabela27[[#This Row],[Lucro]] -> 9.08 | O12: Fii | P12: Day Trader
A13: Nubank | C13: {=_FV(Tabela27[[#This Row],[Nome do ativo]],"Símbolo do ticker",TRUE)} -> B3SA3 | D13: #VALUE! | E13: 1 | F13: 11.25 | G13: {=_FV(Tabela27[[#This Row],[Nome do ativo]],"Preço")*Tabela27[[#This Row],[QTD]]} -> 12.39 | H13: 45708 | J13: =(Tabela27[[#This Row],[Preço Atual/Venda]]-Tabela27[[#This Row],[Valor da compra]]) -> 1.14 | K13: =Tabela27[[#This Row],[Lucro]]+Tabela27[[#This Row],[Dividendos pagos]] -> 1.14 | L13: =J13/(IF(TODAY()-H13=0,1,TODAY()-H13)) -> 0.031666667 | M13: Sim | N13: =Tabela27[[#This Row],[Valor da compra]]+Tabela27[[#This Row],[Lucro]] -> 12.39 | O13: BDR | P13: Renda variável | R13: =SUMIFS(Tabela27[Total],Tabela27[Em posse],"Sim",Tabela27[Tipo],"FII",Tabela27[Operação],"Renda variável") -> 81.72
A14: Nubank | C14: PETR4 | D14: #VALUE! | E14: 1 | F14: =35.02-0.32 -> 34.7 | G14: {=_FV(Tabela27[[#This Row],[Nome do ativo]],"Preço")*Tabela27[[#This Row],[QTD]]} -> 37.67 | H14: 45723 | J14: =(Tabela27[[#This Row],[Preço Atual/Venda]]-Tabela27[[#This Row],[Valor da compra]]) -> 2.97 | K14: =Tabela27[[#This Row],[Lucro]]+Tabela27[[#This Row],[Dividendos pagos]] -> 2.97 | L14: =J14/(IF(TODAY()-H14=0,1,TODAY()-H14)) -> 0.14142857 | M14: Sim | N14: =Tabela27[[#This Row],[Valor da compra]]+Tabela27[[#This Row],[Lucro]] -> 37.67 | O14: BDR | P14: Renda variável
A15: Nubank | C15: MXRF11 | D15: #VALUE! | E15: 2 | F15: =9.07*2 -> 18.14 | G15: {=_FV(Tabela27[[#This Row],[Nome do ativo]],"Preço")*Tabela27[[#This Row],[QTD]]} -> 18.16 | H15: 45723 | J15: =(Tabela27[[#This Row],[Preço Atual/Venda]]-Tabela27[[#This Row],[Valor da compra]]) -> 0.02 | K15: =Tabela27[[#This Row],[Lucro]]+Tabela27[[#This Row],[Dividendos pagos]] -> 0.02 | L15: =J15/(IF(TODAY()-H15=0,1,TODAY()-H15)) -> 0.00095238095 | M15: Sim | N15: =Tabela27[[#This Row],[Valor da compra]]+Tabela27[[#This Row],[Lucro]] -> 18.16 | O15: FII | P15: Renda variável
A16: Nubank | C16: {=_FV(Tabela27[[#This Row],[Nome do ativo]],"Símbolo do ticker",TRUE)} -> ACWI11 | D16: #VALUE! | E16: 1 | F16: 14.28 | G16: {=_FV(Tabela27[[#This Row],[Nome do ativo]],"Preço")*Tabela27[[#This Row],[QTD]]} -> 14.16 | H16: 45723 | J16: =(Tabela27[[#This Row],[Preço Atual/Venda]]-Tabela27[[#This Row],[Valor da compra]]) -> -0.12 | K16: =Tabela27[[#This Row],[Lucro]]+Tabela27[[#This Row],[Dividendos pagos]] -> -0.12 | L16: =J16/(IF(TODAY()-H16=0,1,TODAY()-H16)) -> -0.0057142857 | M16: Sim | N16: =Tabela27[[#This Row],[Valor da compra]]+Tabela27[[#This Row],[Lucro]] -> 14.16 | O16: ETF | P16: Renda variável | R16: Day Trade
A17: Nubank | C17: {=_FV(Tabela27[[#This Row],[Nome do ativo]],"Símbolo do ticker",TRUE)} -> AAZQ11 | D17: #VALUE! | E17: 1 | F17: 6.41 | G17: {=_FV(Tabela27[[#This Row],[Nome do ativo]],"Preço")*Tabela27[[#This Row],[QTD]]} -> 7.14 | H17: 45723 | J17: =(Tabela27[[#This Row],[Preço Atual/Venda]]-Tabela27[[#This Row],[Valor da compra]]) -> 0.73 | K17: =Tabela27[[#This Row],[Lucro]]+Tabela27[[#This Row],[Dividendos pagos]] -> 0.73 | L17: =J17/(IF(TODAY()-H17=0,1,TODAY()-H17)) -> 0.034761905 | M17: Sim | N17: =Tabela27[[#This Row],[Valor da compra]]+Tabela27[[#This Row],[Lucro]] -> 7.14 | O17: ETF | P17: Renda variável
A18: Nubank | C18: MXRF11 | D18: #VALUE! | E18: 1 | F18: 9.06 | G18: {=_FV(Tabela27[[#This Row],[Nome do ativo]],"Preço")*Tabela27[[#This Row],[QTD]]} -> 9.08 | H18: 45730 | J18: =(Tabela27[[#This Row],[Preço Atual/Venda]]-Tabela27[[#This Row],[Valor da compra]]) -> 0.02 | K18: =Tabela27[[#This Row],[Lucro]]+Tabela27[[#This Row],[Dividendos pagos]] -> 0.02 | L18: =J18/(IF(TODAY()-H18=0,1,TODAY()-H18)) -> 0.0014285714 | M18: Sim | N18: =Tabela27[[#This Row],[Valor da compra]]+Tabela27[[#This Row],[Lucro]] -> 9.08 | O18: FII | P18: Renda variável
A19: Nubank | C19: {=_FV(Tabela27[[#This Row],[Nome do ativo]],"Símbolo do ticker",TRUE)} -> BBDC4 | D19: #VALUE! | E19: 3 | F19: 37.55 | G19: {=_FV(Tabela27[[#This Row],[Nome do ativo]],"Preço")*Tabela27[[#This Row],[QTD]]} -> 39.06 | H19: 45737 | J19: =(Tabela27[[#This Row],[Preço Atual/Venda]]-Tabela27[[#This Row],[Valor da compra]]) -> 1.51 | K19: =Tabela27[[#This Row],[Lucro]]+Tabela27[[#This Row],[Dividendos pagos]] -> 1.51 | L19: =J19/(IF(TODAY()-H19=0,1,TODAY()-H19)) -> 0.21571429 | M19: Sim | N19: =Tabela27[[#This Row],[Valor da compra]]+Tabela27[[#This Row],[Lucro]] -> 39.06 | O19: BDR | P19: Renda variável
A20: Nubank | C20: MXRF11 | D20: #VALUE! | E20: 3 | F20: 27.1 | G20: {=_FV(Tabela27[[#This Row],[Nome do ativo]],"Preço")*Tabela27[[#This Row],[QTD]]} -> 27.24 | H20: 45737 | J20: =(Tabela27[[#This Row],[Preço Atual/Venda]]-Tabela27[[#This Row],[Valor da compra]]) -> 0.14 | K20: =Tabela27[[#This Row],[Lucro]]+Tabela27[[#This Row],[Dividendos pagos]] -> 0.14 | L20: =J20/(IF(TODAY()-H20=0,1,TODAY()-H20)) -> 0.02 | M20: Sim | N20: =Tabela27[[#This Row],[Valor da compra]]+Tabela27[[#This Row],[Lucro]] -> 27.24 | O20: FII | P20: Renda variável | R20: Total BDR
R21: =SUMIFS(Tabela27[Total],Tabela27[Tipo],"BDR",Tabela27[Operação],"Renda variável",Tabela27[Em posse],"Sim") -> 90.63
R23: Média de lucro total
R25: =SUM(Tabela27[Lucro Real]) -> 7.18
R27: ETF
D28: HGPO11
R29: =SUMIFS(Tabela27[Total],Tabela27[Tipo],"ETF",Tabela27[Operação],"Renda variável",Tabela27[Em posse],"Sim") -> 21.3

Sheet Tesouro direto
A2: Nome | B2: Valor investido | C2: Valor atual | D2: Data | E2: Vencimento | F2: Em posse | G2: Juros | H2: Lucro
A3: Tesouro nacional | B3: 6.82 | C3: =Tabela9[[#This Row],[Valor investido]]+J7 -> 6.64 | D3: 45726 | E3: 46753 | F3: Sim | G3: 0.1486 | H3: 0.01 | J3: Total
A4: Tesouro nacional | B4: 31.48 | C4: =Tabela9[[#This Row],[Valor investido]]+J8 -> 31.48 | D4: 45737 | E4: 49310 | F4: Sim | G4: 0.1489 | H4: -0.19 | J4: =SUM(Tabela9[Valor atual]) -> 38.12
J6: Lucro
J7: =SUM(Tabela9[Lucro]) -> -0.18
